<?xml version="1.0" ?>
<!-- =================================================================================== -->
<!-- |    This document was autogenerated by xacro from husky_integration.urdf.xacro   | -->
<!-- |    EDITING THIS FILE BY HAND IS NOT RECOMMENDED                                 | -->
<!-- =================================================================================== -->
<!-- Name your robot here -->
<robot name="husky">
  <link name="base_link"/>
  <joint name="base_link_to_chassis" type="fixed">
    <parent link="base_link"/>
    <child link="Chassis"/>
  </joint>
  <link name="Chassis">
    <inertial>
      <origin rpy="0 0 0" xyz="-0.00409511910471694 -7.92446652583267E-05 0.378414294437562"/>
      <mass value="98.2091641278018"/>
      <inertia ixx="2.43706506980442" ixy="-0.000192777669574608" ixz="1.33323634062716E-05" iyy="7.76169144977584" iyz="0.000771573849380231" izz="9.53629526187739"/>
    </inertial>
    <visual>
      <origin rpy="0 0 0" xyz="0 0 0"/>
      <geometry>
        <mesh filename="package://husky/meshes/Chassis.STL"/>
      </geometry>
      <material name="">
        <color rgba="0.792156862745098 0.819607843137255 0.933333333333333 1"/>
      </material>
    </visual>
    <collision>
      <origin rpy="0 0 0" xyz="0 0 0"/>
      <geometry>
        <mesh filename="package://husky/meshes/Chassis.STL"/>
      </geometry>
    </collision>
  </link>
  <link name="Front_L_lateral">
    <inertial>
      <origin rpy="0 0 0" xyz="6.32840144176861E-09 5.59948220568707E-08 -0.0900878133769817"/>
      <mass value="1.56068233140516"/>
      <inertia ixx="0.00440193254427216" ixy="-3.88814756276166E-06" ixz="1.17225961295948E-09" iyy="0.00468417393852864" iyz="-1.52397334132621E-08" izz="0.00215293929877346"/>
    </inertial>
    <visual>
      <origin rpy="0 0 0" xyz="0 0 0"/>
      <geometry>
        <mesh filename="package://husky/meshes/Front_L_lateral.STL"/>
      </geometry>
      <material name="">
        <color rgba="0.792156862745098 0.819607843137255 0.933333333333333 1"/>
      </material>
    </visual>
    <collision>
      <origin rpy="0 0 0" xyz="0 0 0"/>
      <geometry>
        <mesh filename="package://husky/meshes/Front_L_lateral.STL"/>
      </geometry>
    </collision>
  </link>
  <joint name="Front_L_lateral_joint" type="revolute">
    <origin rpy="0 0 3.14159265358979" xyz="0.277600320101877 0.1778 0.2666746"/>
    <parent link="Chassis"/>
    <child link="Front_L_lateral"/>
    <axis xyz="0 0 1"/>
    <limit effort="30" lower="-0.5" upper="0.5" velocity="100"/>
  </joint>
  <link name="wheel_FL">
    <inertial>
      <origin rpy="0 0 0" xyz="0 -5.55111512312578E-17 -1.38413591995734E-05"/>
      <mass value="2.3833672867985"/>
      <inertia ixx="0.00752117923800553" ixy="1.60333390448917E-18" ixz="-6.91178884959509E-18" iyy="0.00752117923800553" iyz="-1.52686865250883E-18" izz="0.0127375442021922"/>
    </inertial>
    <visual>
      <origin rpy="0 0 0" xyz="0 0 0"/>
      <geometry>
        <mesh filename="package://husky/meshes/wheel_FL.STL"/>
      </geometry>
      <material name="">
        <color rgba="0.792156862745098 0.819607843137255 0.933333333333333 1"/>
      </material>
    </visual>
    <collision>
      <origin rpy="0 0 0" xyz="0 0 0"/>
      <geometry>
        <mesh filename="package://husky/meshes/wheel_FL.STL"/>
      </geometry>
    </collision>
  </link>
  <joint name="wheel_FL_joint" type="continuous">
    <origin rpy="1.5707963267949 0 0.0137725196566579" xyz="0 -0.00025397591072851 -0.165100000000001"/>
    <parent link="Front_L_lateral"/>
    <child link="wheel_FL"/>
    <axis xyz="-0.0576811894510143 0 -0.998335054169449"/>
  </joint>
  <link name="Front_R_lateral">
    <inertial>
      <origin rpy="0 0 0" xyz="-9.68773519738342E-09 -5.52423745220354E-08 -0.0900878142178023"/>
      <mass value="1.56068241667093"/>
      <inertia ixx="0.00440249549661789" ixy="1.31752084700576E-05" ixz="-2.45792301781752E-10" iyy="0.0046836116815121" iyz="1.53412531549081E-08" izz="0.0021529393553379"/>
    </inertial>
    <visual>
      <origin rpy="0 0 0" xyz="0 0 0"/>
      <geometry>
        <mesh filename="package://husky/meshes/Front_R_lateral.STL"/>
      </geometry>
      <material name="">
        <color rgba="0.792156862745098 0.819607843137255 0.933333333333333 1"/>
      </material>
    </visual>
    <collision>
      <origin rpy="0 0 0" xyz="0 0 0"/>
      <geometry>
        <mesh filename="package://husky/meshes/Front_R_lateral.STL"/>
      </geometry>
    </collision>
  </link>
  <joint name="Front_R_lateral_joint" type="revolute">
    <origin rpy="0 0 3.14159265358979" xyz="0.277600320101878 -0.1778 0.266674599999999"/>
    <parent link="Chassis"/>
    <child link="Front_R_lateral"/>
    <axis xyz="0 0 1"/>
    <limit effort="30" lower="-0.5" upper="0.5" velocity="100"/>
  </joint>
  <link name="wheel_FR">
    <inertial>
      <origin rpy="0 0 0" xyz="0 0 1.38413591996983E-05"/>
      <mass value="2.3833672867985"/>
      <inertia ixx="0.00752117923800552" ixy="1.59902634902589E-18" ixz="-3.55076211489003E-18" iyy="0.00752117923800552" iyz="3.07306291419973E-18" izz="0.0127375442021922"/>
    </inertial>
    <visual>
      <origin rpy="0 0 0" xyz="0 0 0"/>
      <geometry>
        <mesh filename="package://husky/meshes/wheel_FR.STL"/>
      </geometry>
      <material name="">
        <color rgba="0.792156862745098 0.819607843137255 0.933333333333333 1"/>
      </material>
    </visual>
    <collision>
      <origin rpy="0 0 0" xyz="0 0 0"/>
      <geometry>
        <mesh filename="package://husky/meshes/wheel_FR.STL"/>
      </geometry>
    </collision>
  </link>
  <joint name="wheel_FR_joint" type="continuous">
    <origin rpy="1.5707963267949 0 -0.0467308215193505" xyz="1.18653090454834E-05 0.000253722711709981 -0.165100000000001"/>
    <parent link="Front_R_lateral"/>
    <child link="wheel_FR"/>
    <axis xyz="0 0 1"/>
  </joint>
  <link name="Back_L_lateral">
    <inertial>
      <origin rpy="0 0 0" xyz="-7.09657854702783E-09 0.0750121877140557 0.000254056245475087"/>
      <mass value="1.56068222160202"/>
      <inertia ixx="0.00440187852124776" ixy="-9.62172481420887E-10" ixz="1.5643067493271E-11" iyy="0.00215293922624177" iyz="-1.51787007981222E-08" izz="0.00468422707038218"/>
    </inertial>
    <visual>
      <origin rpy="0 0 0" xyz="0 0 0"/>
      <geometry>
        <mesh filename="package://husky/meshes/Back_L_lateral.STL"/>
      </geometry>
      <material name="">
        <color rgba="0.792156862745098 0.819607843137255 0.933333333333333 1"/>
      </material>
    </visual>
    <collision>
      <origin rpy="0 0 0" xyz="0 0 0"/>
      <geometry>
        <mesh filename="package://husky/meshes/Back_L_lateral.STL"/>
      </geometry>
    </collision>
  </link>
  <joint name="Back_L_lateral_joint" type="fixed">
    <origin rpy="1.5707963267949 0 3.14159265358979" xyz="-0.38192523364007 0.177546 0.101574599999999"/>
    <parent link="Chassis"/>
    <child link="Back_L_lateral"/>
    <axis xyz="0 0 0"/>
  </joint>
  <link name="wheel_LB">
    <inertial>
      <origin rpy="0 0 0" xyz="1.11022302462516E-16 0 1.38413591996289E-05"/>
      <mass value="2.3833672867985"/>
      <inertia ixx="0.00752117923800552" ixy="-5.95487152246847E-19" ixz="5.41377533629747E-18" iyy="0.00752117923800552" iyz="-5.68895854154682E-18" izz="0.0127375442021922"/>
    </inertial>
    <visual>
      <origin rpy="0 0 0" xyz="0 0 0"/>
      <geometry>
        <mesh filename="package://husky/meshes/wheel_LB.STL"/>
      </geometry>
      <material name="">
        <color rgba="0.792156862745098 0.819607843137255 0.933333333333333 1"/>
      </material>
    </visual>
    <collision>
      <origin rpy="0 0 0" xyz="0 0 0"/>
      <geometry>
        <mesh filename="package://husky/meshes/wheel_LB.STL"/>
      </geometry>
    </collision>
  </link>
  <joint name="wheel_LB_joint" type="continuous">
    <origin rpy="0 0 0" xyz="0 0 0"/>
    <parent link="Back_L_lateral"/>
    <child link="wheel_LB"/>
    <axis xyz="0 0 1"/>
  </joint>
  <link name="Back_R_lateral">
    <inertial>
      <origin rpy="0 0 0" xyz="6.28080043529877E-09 0.0663892566855093 0.0201847240194173"/>
      <mass value="1.76339054861497"/>
      <inertia ixx="0.00495428485328606" ixy="9.62172475562444E-10" ixz="1.5643065374316E-11" iyy="0.00270534555828007" iyz="1.51787008022865E-08" izz="0.00472100874970409"/>
    </inertial>
    <visual>
      <origin rpy="0 0 0" xyz="0 0 0"/>
      <geometry>
        <mesh filename="package://husky/meshes/Back_R_lateral.STL"/>
      </geometry>
      <material name="">
        <color rgba="0.792156862745098 0.819607843137255 0.933333333333333 1"/>
      </material>
    </visual>
    <collision>
      <origin rpy="0 0 0" xyz="0 0 0"/>
      <geometry>
        <mesh filename="package://husky/meshes/Back_R_lateral.STL"/>
      </geometry>
    </collision>
  </link>
  <joint name="Back_R_lateral_joint" type="fixed">
    <origin rpy="1.5707963267949 0 3.14159265358979" xyz="-0.381925233640069 -0.177546 0.101574599999999"/>
    <parent link="Chassis"/>
    <child link="Back_R_lateral"/>
    <axis xyz="0 0 0"/>
  </joint>
  <link name="wheel_RB">
    <inertial>
      <origin rpy="0 0 0" xyz="1.11022302462516E-16 -5.55111512312578E-17 -1.38413591996983E-05"/>
      <mass value="2.3833672867985"/>
      <inertia ixx="0.00752117923800552" ixy="-1.0020935174662E-18" ixz="6.14617236406643E-18" iyy="0.00752117923800552" iyz="5.51223971161121E-18" izz="0.0127375442021922"/>
    </inertial>
    <visual>
      <origin rpy="0 0 0" xyz="0 0 0"/>
      <geometry>
        <mesh filename="package://husky/meshes/wheel_RB.STL"/>
      </geometry>
      <material name="">
        <color rgba="0.792156862745098 0.819607843137255 0.933333333333333 1"/>
      </material>
    </visual>
    <collision>
      <origin rpy="0 0 0" xyz="0 0 0"/>
      <geometry>
        <mesh filename="package://husky/meshes/wheel_RB.STL"/>
      </geometry>
    </collision>
  </link>
  <joint name="wheel_RB_joint" type="continuous">
    <origin rpy="0 0 0" xyz="0 0 0"/>
    <parent link="Back_R_lateral"/>
    <child link="wheel_RB"/>
    <axis xyz="0 0 1"/>
  </joint>
  <transmission name="wheel_BR_trans">
    <type>transmission_interface/SimpleTransmission</type>
    <joint name="wheel_RB_joint">
      <hardwareInterface>hardware_interface/VelocityJointInterface</hardwareInterface>
    </joint>
    <actuator name="wheel_BR_motor">
      <hardwareInterface>hardware_interface/VelocityJointInterface</hardwareInterface>
    </actuator>
  </transmission>
  <transmission name="wheel_BL_trans">
    <type>transmission_interface/SimpleTransmission</type>
    <joint name="wheel_LB_joint">
      <hardwareInterface>hardware_interface/VelocityJointInterface</hardwareInterface>
    </joint>
    <actuator name="wheel_BL_motor">
      <hardwareInterface>hardware_interface/VelocityJointInterface</hardwareInterface>
    </actuator>
  </transmission>
  <transmission name="Front_R_lateral_trans">
    <type>transmission_interface/SimpleTransmission</type>
    <joint name="Front_R_lateral_joint">
      <hardwareInterface>hardware_interface/EffortJointInterface</hardwareInterface>
    </joint>
    <actuator name="Front_R_lateral_motor">
      <hardwareInterface>hardware_interface/EffortJointInterface</hardwareInterface>
    </actuator>
  </transmission>
  <transmission name="Front_L_lateral_trans">
    <type>transmission_interface/SimpleTransmission</type>
    <joint name="Front_L_lateral_joint">
      <hardwareInterface>hardware_interface/EffortJointInterface</hardwareInterface>
    </joint>
    <actuator name="Front_L_lateral_motor">
      <hardwareInterface>hardware_interface/EffortJointInterface</hardwareInterface>
    </actuator>
  </transmission>
  <link name="base_laser">
    <inertial>
      <origin rpy="0 0 0" xyz="-0.00029774 0.0066667 0.00013047"/>
      <mass value="0.15717"/>
      <inertia ixx="6.7885E-05" ixy="-1.3987E-07" ixz="-8.1554E-07" iyy="0.00013173" iyz="-9.0932E-08" izz="7.1972E-05"/>
    </inertial>
    <visual>
      <origin rpy="0 0 0" xyz="0 0 0"/>
      <geometry>
        <mesh filename="package://husky/meshes/ydlidar.dae"/>
      </geometry>
      <material name="">
        <color rgba="0.64706 0.61961 0.58824 1"/>
      </material>
    </visual>
    <collision>
      <origin rpy="0 0 0" xyz="0 0 0"/>
      <geometry>
        <mesh filename="package://husky/meshes/ydlidar.dae"/>
      </geometry>
    </collision>
  </link>
  <link name="laser_frame">
    <inertial>
      <origin rpy="0 0 0" xyz="-0.00036659 0.00064155 -0.00027052"/>
      <mass value="0.25482"/>
      <inertia ixx="8.9194E-05" ixy="1.8116E-07" ixz="3.6435E-08" iyy="0.00018279" iyz="2.423E-07" izz="0.00011103"/>
    </inertial>
    <!--visual>
      <origin
        xyz="0 0 0"
        rpy="0 0 0" />
      <geometry>
        <mesh
          filename="package://husky/meshes/ydlidar.dae" />
      </geometry>
      <material
        name="">
        <color
          rgba="0.64706 0.61961 0.58824 1" />
      </material>
    </visual-->
    <!--collision>
      <origin
        xyz="0 0 0"
        rpy="0 0 0" />
      <geometry>
        <mesh
          filename="package://husky/meshes/ydlidar.dae" />
      </geometry>
    </collision-->
  </link>
  <joint name="laser_joint" type="fixed">
    <origin rpy="0 0 0" xyz="0 0 0.03172"/>
    <parent link="base_laser"/>
    <child link="laser_frame"/>
    <axis xyz="0 0 0"/>
  </joint>
  <!-- Add your gazebo sensors here -->
  <gazebo reference="base_laser">
    <!-- <gravity>true</gravity> -->
    <!-- Gazebo has fixed set of Sensors types. Check them out here <> -->
    <sensor name="laser" type="ray">
      <!-- Add in your sensor characteristics -->
      <pose> 0 0 0 0 0 0 </pose>
      <visualise>true</visualise>
      <update_rate>40</update_rate>
      <!-- <always_on>true</always_on> -->
      <ray>
        <scan>
          <horizontal>
            <samples>720</samples>
            <resolution>1</resolution>
            <min_angle>-1.570796</min_angle>
            <max_angle>1.570796</max_angle>
          </horizontal>
        </scan>
        <range>
          <min>0.10</min>
          <max>30.0</max>
          <resolution>0.01</resolution>
        </range>
        <noise>
          <type>gaussian</type>
          <mean>0.0</mean>
          <stddev>0.01</stddev>
        </noise>
      </ray>
      <plugin filename="libgazebo_ros_laser.so" name="gazebo_ros_head_hokuyo_controller">
        <!-- Use topic name as /my_robot/scan -->
        <topicName>/husky/scan</topicName>
        <frameName>laser_frame</frameName>
      </plugin>
    </sensor>
  </gazebo>
  <!--  Gazebo plugin for control here is already added for you -->
  <gazebo>
    <plugin filename="libgazebo_ros_control.so" name="gazebo_ros_control">
      <robotNamespace>/husky</robotNamespace>
      <robotSimType>gazebo_ros_control/DefaultRobotHWSim</robotSimType>
      <legacyModeNS>true</legacyModeNS>
    </plugin>
  </gazebo>
  <!-- Create a joint between your robot and sensor -->
  <joint name="link_to_lidar" type="fixed">
    <parent link="Chassis"/>
    <child link="base_laser"/>
    <origin rpy="0 0 0" xyz="0 0 0.485775"/>
  </joint>
</robot>
